Workbook

Sheet accounts
A1: account | B1: sector | C1: year_established | D1: revenue | E1: employees | F1: office_location | G1: subsidiary_of | H1: Parent_Validation
A2: Kan-code | B2: software | C2: 1982 | D2: 11698.03 | E2: 34288 | F2: United States | H2: =IF(G2="","No Parent",IF(COUNTIF($A$2:$A$86,G2)>0,"Valid Parent","Parent Not Found")) -> No Parent
A3: Xx-holding | B3: finance | C3: 1993 | D3: 7537.24 | E3: 20293 | F3: United States | H3: =IF(G3="","No Parent",IF(COUNTIF($A$2:$A$86,G3)>0,"Valid Parent","Parent Not Found")) -> No Parent
A4: Initech | B4: telecommunications | C4: 1994 | D4: 6395.05 | E4: 20275 | F4: United States | H4: =IF(G4="","No Parent",IF(COUNTIF($A$2:$A$86,G4)>0,"Valid Parent","Parent Not Found")) -> No Parent
A5: Ganjaflex | B5: retail | C5: 1995 | D5: 5158.71 | E5: 17479 | F5: Japan | H5: =IF(G5="","No Parent",IF(COUNTIF($A$2:$A$86,G5)>0,"Valid Parent","Parent Not Found")) -> No Parent
A6: Scotfind | B6: software | C6: 1996 | D6: 6354.87 | E6: 16780 | F6: United States | G6: Bubba Gump | H6: =IF(G6="","No Parent",IF(COUNTIF($A$2:$A$86,G6)>0,"Valid Parent","Parent Not Found")) -> Valid Parent
A7: Hottechi | B7: technolgy | C7: 1997 | D7: 8170.38 | E7: 16499 | F7: Korea | H7: =IF(G7="","No Parent",IF(COUNTIF($A$2:$A$86,G7)>0,"Valid Parent","Parent Not Found")) -> No Parent
A8: Zotware | B8: software | C8: 1979 | D8: 4478.47 | E8: 13809 | F8: United States | H8: =IF(G8="","No Parent",IF(COUNTIF($A$2:$A$86,G8)>0,"Valid Parent","Parent Not Found")) -> No Parent
A9: Konex | B9: technolgy | C9: 1980 | D9: 7708.38 | E9: 13756 | F9: United States | H9: =IF(G9="","No Parent",IF(COUNTIF($A$2:$A$86,G9)>0,"Valid Parent","Parent Not Found")) -> No Parent
A10: Dontechi | B10: software | C10: 1982 | D10: 4618 | E10: 10083 | F10: United States | H10: =IF(G10="","No Parent",IF(COUNTIF($A$2:$A$86,G10)>0,"Valid Parent","Parent Not Found")) -> No Parent
A11: Y-corporation | B11: employment | C11: 1983 | D11: 2871.35 | E11: 9561 | F11: United States | H11: =IF(G11="","No Parent",IF(COUNTIF($A$2:$A$86,G11)>0,"Valid Parent","Parent Not Found")) -> No Parent
A12: Mathtouch | B12: marketing | C12: 1984 | D12: 3027.46 | E12: 9516 | F12: Jordan | H12: =IF(G12="","No Parent",IF(COUNTIF($A$2:$A$86,G12)>0,"Valid Parent","Parent Not Found")) -> No Parent
A13: Labdrill | B13: medical | C13: 1985 | D13: 2741.37 | E13: 9226 | F13: United States | H13: =IF(G13="","No Parent",IF(COUNTIF($A$2:$A$86,G13)>0,"Valid Parent","Parent Not Found")) -> No Parent
A14: Inity | B14: marketing | C14: 1986 | D14: 2403.58 | E14: 8801 | F14: United States | H14: =IF(G14="","No Parent",IF(COUNTIF($A$2:$A$86,G14)>0,"Valid Parent","Parent Not Found")) -> No Parent
A15: Rangreen | B15: technolgy | C15: 1987 | D15: 2938.67 | E15: 8775 | F15: Panama | H15: =IF(G15="","No Parent",IF(COUNTIF($A$2:$A$86,G15)>0,"Valid Parent","Parent Not Found")) -> No Parent
A16: Treequote | B16: telecommunications | C16: 1988 | D16: 5266.09 | E16: 8595 | F16: United States | G16: Sonron | H16: =IF(G16="","No Parent",IF(COUNTIF($A$2:$A$86,G16)>0,"Valid Parent","Parent Not Found")) -> Valid Parent
A17: Xx-zobam | B17: entertainment | C17: 1989 | D17: 3838.39 | E17: 8274 | F17: United States | H17: =IF(G17="","No Parent",IF(COUNTIF($A$2:$A$86,G17)>0,"Valid Parent","Parent Not Found")) -> No Parent
A18: Fasehatice | B18: retail | C18: 1990 | D18: 4968.91 | E18: 7523 | F18: United States | H18: =IF(G18="","No Parent",IF(COUNTIF($A$2:$A$86,G18)>0,"Valid Parent","Parent Not Found")) -> No Parent
A19: Funholding | B19: finance | C19: 1991 | D19: 2819.5 | E19: 7227 | F19: United States | G19: Golddex | H19: =IF(G19="","No Parent",IF(COUNTIF($A$2:$A$86,G19)>0,"Valid Parent","Parent Not Found")) -> Valid Parent
A20: Ron-tech | B20: medical | C20: 1992 | D20: 3922.42 | E20: 6837 | F20: United States | H20: =IF(G20="","No Parent",IF(COUNTIF($A$2:$A$86,G20)>0,"Valid Parent","Parent Not Found")) -> No Parent
A21: Cheers | B21: entertainment | C21: 1993 | D21: 4269.9 | E21: 6472 | F21: United States | G21: Massive Dynamic | H21: =IF(G21="","No Parent",IF(COUNTIF($A$2:$A$86,G21)>0,"Valid Parent","Parent Not Found")) -> Valid Parent
A22: Silis | B22: medical | C22: 1994 | D22: 2818.38 | E22: 6290 | F22: United States | H22: =IF(G22="","No Parent",IF(COUNTIF($A$2:$A$86,G22)>0,"Valid Parent","Parent Not Found")) -> No Parent
A23: Faxquote | B23: telecommunications | C23: 1995 | D23: 1825.82 | E23: 5595 | F23: United States | G23: Sonron | H23: =IF(G23="","No Parent",IF(COUNTIF($A$2:$A$86,G23)>0,"Valid Parent","Parent Not Found")) -> Valid Parent
A24: Singletechno | B24: retail | C24: 1996 | D24: 2214.94 | E24: 5374 | F24: United States | H24: =IF(G24="","No Parent",IF(COUNTIF($A$2:$A$86,G24)>0,"Valid Parent","Parent Not Found")) -> No Parent
A25: Warephase | B25: services | C25: 1997 | D25: 2041.73 | E25: 5276 | F25: United States | H25: =IF(G25="","No Parent",IF(COUNTIF($A$2:$A$86,G25)>0,"Valid Parent","Parent Not Found")) -> No Parent
A26: Umbrella Corporation | B26: finance | C26: 1998 | D26: 2022.14 | E26: 5113 | F26: United States | H26: =IF(G26="","No Parent",IF(COUNTIF($A$2:$A$86,G26)>0,"Valid Parent","Parent Not Found")) -> No Parent
A27: Sonron | B27: telecommunications | C27: 1999 | D27: 1699.85 | E27: 5108 | F27: United States | H27: =IF(G27="","No Parent",IF(COUNTIF($A$2:$A$86,G27)>0,"Valid Parent","Parent Not Found")) -> No Parent
A28: Goodsilron | B28: marketing | C28: 2000 | D28: 2952.73 | E28: 5107 | F28: United States | H28: =IF(G28="","No Parent",IF(COUNTIF($A$2:$A$86,G28)>0,"Valid Parent","Parent Not Found")) -> No Parent
A29: Plexzap | B29: retail | C29: 2001 | D29: 2437.85 | E29: 4874 | F29: United States | H29: =IF(G29="","No Parent",IF(COUNTIF($A$2:$A$86,G29)>0,"Valid Parent","Parent Not Found")) -> No Parent
A30: Isdom | B30: medical | C30: 2002 | D30: 3178.24 | E30: 4540 | F30: United States | H30: =IF(G30="","No Parent",IF(COUNTIF($A$2:$A$86,G30)>0,"Valid Parent","Parent Not Found")) -> No Parent
A31: Plussunin | B31: retail | C31: 2003 | D31: 1419.98 | E31: 4018 | F31: United States | H31: =IF(G31="","No Parent",IF(COUNTIF($A$2:$A$86,G31)>0,"Valid Parent","Parent Not Found")) -> No Parent
A32: Lexiqvolax | B32: medical | C32: 2004 | D32: 1618.89 | E32: 3889 | F32: United States | H32: =IF(G32="","No Parent",IF(COUNTIF($A$2:$A$86,G32)>0,"Valid Parent","Parent Not Found")) -> No Parent
A33: Yearin | B33: retail | C33: 2005 | D33: 2261.05 | E33: 3851 | F33: United States | H33: =IF(G33="","No Parent",IF(COUNTIF($A$2:$A$86,G33)>0,"Valid Parent","Parent Not Found")) -> No Parent
A34: Stanredtax | B34: finance | C34: 1987 | D34: 1698.2 | E34: 3798 | F34: United States | H34: =IF(G34="","No Parent",IF(COUNTIF($A$2:$A$86,G34)>0,"Valid Parent","Parent Not Found")) -> No Parent
A35: Finjob | B35: employment | C35: 1988 | D35: 2059.9 | E35: 3644 | F35: United States | H35: =IF(G35="","No Parent",IF(COUNTIF($A$2:$A$86,G35)>0,"Valid Parent","Parent Not Found")) -> No Parent
... A38: Newex | B38: services | C38: 1991 | D38: 1012.72 | E38: 3492 | F38: Germany | H38: =IF(G38="","No Parent",IF(COUNTIF($A$2:$A$86,G38)>0,"Valid Parent","Parent Not Found")) -> No Parent
A39: Donquadtech | B39: technolgy | C39: 1992 | D39: 1712.68 | E39: 3194 | F39: United States | G39: Acme Corporation | H39: =IF(G39="","No Parent",IF(COUNTIF($A$2:$A$86,G39)>0,"Valid Parent","Parent Not Found")) -> Valid Parent
A40: Bluth Company | B40: technolgy | C40: 1993 | D40: 1242.32 | E40: 3027 | F40: United States | G40: Acme Corporation | H40: =IF(G40="","No Parent",IF(COUNTIF($A$2:$A$86,G40)>0,"Valid Parent","Parent Not Found")) -> Valid Parent
A41: Rantouch | B41: telecommunications | C41: 1994 | D41: 1188.42 | E41: 3015 | F41: United States | H41: =IF(G41="","No Parent",IF(COUNTIF($A$2:$A$86,G41)>0,"Valid Parent","Parent Not Found")) -> No Parent
A42: dambase | B42: marketing | C42: 1995 | D42: 2173.98 | E42: 2928 | F42: United States | G42: Inity | H42: =IF(G42="","No Parent",IF(COUNTIF($A$2:$A$86,G42)>0,"Valid Parent","Parent Not Found")) -> Valid Parent
...

Sheet pivot
A3: Row Labels | B3: Count of account
A4: employment | B4: 4
A5: entertainment | B5: 6
A6: finance | B6: 8
A7: marketing | B7: 8
A8: medical | B8: 12
A9: retail | B9: 17
A10: services | B10: 5
A11: software | B11: 7
A12: technolgy | B12: 12
A13: telecommunications | B13: 6
A14: Grand Total | B14: 85
A16: Row Labels | B16: Count of account
A17: Belgium | B17: 1
A18: Brazil | B18: 1
A19: China | B19: 1
A20: Germany | B20: 1
A21: Italy | B21: 1
A22: Japan | B22: 1
A23: Jordan | B23: 1
A24: Kenya | B24: 1
A25: Korea | B25: 1
A26: Norway | B26: 1
A27: Panama | B27: 1
A28: Philipines | B28: 1
... A32: Grand Total | B32: 85
A34: Row Labels | B34: Count of account
A35: Acme Corporation | B35: 4
A36: Bubba Gump | B36: 2
A37: Golddex | B37: 2
A38: Inity | B38: 2
A39: Massive Dynamic | B39: 1
A40: Sonron | B40: 3
A41: Warephase | B41: 1
A42: (blank) | B42: 70
A43: Grand Total | B43: 85

Sheet Data Profile
A1: Column | B1: Total Rows | C1: Missing | E1: Min of EMP | F1: Max of EMP
A2: account | B2: 85 | C2: =COUNTBLANK(accounts!A2:A86) -> 0 | E2: =MIN(accounts[employees]) -> 9 | F2: =MAX(accounts[employees]) -> 34288
A3: sector | B3: 85 | C3: =COUNTBLANK(accounts!B2:B86) -> 0
A4: year_established | B4: 85 | C4: =COUNTBLANK(accounts!C2:C86) -> 0
A5: revenue | B5: 85 | C5: =COUNTBLANK(accounts!D2:D86) -> 0 | E5: Min of Revenue | F5: Max of Revenue
A6: employees | B6: 85 | C6: =COUNTBLANK(accounts!E2:E86) -> 0 | E6: =MIN(accounts[revenue]) -> 4.54 | F6: =MAX(accounts[revenue]) -> 11698.03
A7: office_location | B7: 85 | C7: =COUNTBLANK(accounts!F2:F86) -> 0
A8: subsidiary_of | B8: 85 | C8: =COUNTBLANK(accounts!G2:G86) -> 70
E9: Min of year | F9: Max of year
E10: =MIN(accounts[year_established]) -> 1979 | F10: =MAX(accounts[year_established]) -> 2017
E13: future years | F13: =COUNTIF(accounts[year_established],">2026") -> 0
E14: negative | F14: =COUNTIF(accounts[year_established],"<0") -> 0
